<?xml version="1.0" ?>
<!-- =================================================================================== -->
<!-- |    This document was autogenerated by xacro from /home/mtgoldst/ssl_robots/nbv/urdf/nbv.urdf.xacro | -->
<!-- |    EDITING THIS FILE BY HAND IS NOT RECOMMENDED                                 | -->
<!-- =================================================================================== -->
<robot name="nbv">
  <!-- Base -->
  <link name="base_link">
    <visual>
      <origin rpy="0 0 0" xyz="0 0 0"/>
      <geometry>
        <mesh filename="package://ssl_robots_pkg/ssl_robots/nbv/urdf/stl/mount.stl"/>
      </geometry>
    </visual>
    <collision>
      <origin rpy="0 0 0" xyz="0 0 0"/>
      <geometry>
        <mesh filename="package://ssl_robots_pkg/ssl_robots/nbv/urdf/stl/mount.stl"/>
      </geometry>
    </collision>
    <inertial>
      <mass value="0.1" />
      <inertia ixx="0.03" iyy="0.03" izz="0.03" ixy="0.0" ixz="0.0" iyz="0.0" />
    </inertial>
  </link>
  <!-- Base-Seg1 -->
  <link name="base-seg1">
    <visual>
      <origin rpy="0 0 -1.57079632679" xyz="0 0 -0.2491"/>
      <geometry>
        <mesh filename="package://ssl_robots_pkg/ssl_robots/nbv/urdf/stl/mount-seg1.stl"/>
      </geometry>
    </visual>
    <collision>
      <origin rpy="0 0 -1.57079632679" xyz="0 0 -0.2491"/>
      <geometry>
        <mesh filename="package://ssl_robots_pkg/ssl_robots/nbv/urdf/stl/mount-seg1.stl"/>
      </geometry>
    </collision>
    <inertial>
      <mass value="0.1"/>
      <inertia ixx="0.03" ixy="0.0" ixz="0.0" iyy="0.03" iyz="0.0" izz="0.03"/>
    </inertial>
  </link>
  <joint name="joint1" type="revolute">
    <parent link="base_link"/>
    <child link="base-seg1"/>
    <origin rpy="0 0 0" xyz="0 0 0.2872"/>
    <axis xyz="0 0 1"/>
    <limit effort="300" lower="-3.14159" upper="3.14159" velocity="0.25"/>
  </joint>
  <!-- Seg1 -->
  <link name="seg1">
    <visual>
      <origin rpy="0 1.57079632679 -1.57079632679" xyz="0 0 0"/>
      <geometry>
        <mesh filename="package://ssl_robots_pkg/ssl_robots/nbv/urdf/stl/seg1.stl"/>
      </geometry>
    </visual>
    <collision>
      <origin rpy="0 1.57079632679 -1.57079632679" xyz="0 0 0"/>
      <geometry>
        <mesh filename="package://ssl_robots_pkg/ssl_robots/nbv/urdf/stl/seg1.stl"/>
      </geometry>
    </collision>
    <inertial>
      <mass value="0.1"/>
      <inertia ixx="0.03" ixy="0.0" ixz="0.0" iyy="0.03" iyz="0.0" izz="0.03"/>
    </inertial>
  </link>
  <joint name="joint2" type="revolute">
    <parent link="base-seg1"/>
    <child link="seg1"/>
    <origin rpy="1.57079632679 0 0" xyz="0 0 0"/>
    <axis xyz="0 0 1"/>
    <limit effort="300" lower="-0.785" upper="3.925" velocity="0.25"/>
  </joint>
  <!-- Seg1-Seg2 -->
  <link name="seg1-seg2">
    <visual>
      <origin rpy="0 1.57079632679 0" xyz="0 0 0"/>
      <geometry>
        <mesh filename="package://ssl_robots_pkg/ssl_robots/nbv/urdf/stl/seg1-seg2.stl"/>
      </geometry>
    </visual>
    <collision>
      <origin rpy="0 1.57079632679 0" xyz="0 0 0"/>
      <geometry>
        <mesh filename="package://ssl_robots_pkg/ssl_robots/nbv/urdf/stl/seg1-seg2.stl"/>
      </geometry>
    </collision>
    <inertial>
      <mass value="0.1"/>
      <inertia ixx="0.03" ixy="0.0" ixz="0.0" iyy="0.03" iyz="0.0" izz="0.03"/>
    </inertial>
  </link>
  <joint name="joint3" type="revolute">
    <parent link="seg1"/>
    <child link="seg1-seg2"/>
    <origin rpy="3.14159265359 0 0" xyz="0.5589 0 0"/>
    <axis xyz="0 0 1"/>
    <limit effort="300" lower="-1.5707" upper="1.5707" velocity="0.25"/>
  </joint>
  <!-- Seg2 -->
  <link name="seg2">
    <visual>
      <origin rpy="0 0 1.57079632679" xyz="0 0 0.1"/>
      <geometry>
        <mesh filename="package://ssl_robots_pkg/ssl_robots/nbv/urdf/stl/seg2.stl"/>
      </geometry>
    </visual>
    <collision>
      <origin rpy="0 0 1.57079632679" xyz="0 0 0.1"/>
      <geometry>
        <mesh filename="package://ssl_robots_pkg/ssl_robots/nbv/urdf/stl/seg2.stl"/>
      </geometry>
    </collision>
    <inertial>
      <mass value="0.1"/>
      <inertia ixx="0.03" ixy="0.0" ixz="0.0" iyy="0.03" iyz="0.0" izz="0.03"/>
    </inertial>
  </link>
  <joint name="joint4" type="continuous">
    <parent link="seg1-seg2"/>
    <child link="seg2"/>
    <origin rpy="1.57079632679 0 0" xyz="0.15140 0 0"/>
    <axis xyz="0 0 1"/>
    <limit effort="300" lower="-3.14159" upper="3.14159" velocity="0.25"/>
  </joint>
  <!-- End -->
  <link name="end">
    <visual>
      <origin rpy="0 1.57079632679 -1.57079632679" xyz="0 0 0"/>
      <geometry>
        <mesh filename="package://ssl_robots_pkg/ssl_robots/nbv/urdf/stl/end.stl"/>
      </geometry>
    </visual>
    <collision>
      <origin rpy="0 1.57079632679 -1.57079632679" xyz="0 0 0"/>
      <geometry>
        <mesh filename="package://ssl_robots_pkg/ssl_robots/nbv/urdf/stl/end.stl"/>
      </geometry>
    </collision>
    <inertial>
      <mass value="0.1"/>
      <inertia ixx="0.03" ixy="0.0" ixz="0.0" iyy="0.03" iyz="0.0" izz="0.03"/>
    </inertial>
  </link>
  <joint name="joint5" type="revolute">
    <parent link="seg2"/>
    <child link="end"/>
    <origin rpy="-1.57079632679 0 0" xyz="0 0 0.5388"/>
    <axis xyz="0 0 1"/>
    <limit effort="300" lower="-1.78" upper="1.78" velocity="0.25"/>
  </joint>
  <!-- Manipulator -->
  <!-- Another joint for the rotation of whatever is attached to the end of NBV.
    As there is no model for this, it's currently just a big cube when uncommented. -->
  <link name="manip">
    <visual>
      <origin rpy="0 0 0" xyz="0 0 0"/>
      <geometry>
        <box size="0.1 0.1 0.1"/>
      </geometry>
    </visual>
    <collision>
      <origin rpy="0 0 0" xyz="0 0 0"/>
      <geometry>
        <box size="0.1 0.1 0.1"/>
      </geometry>
    </collision>
    <inertial>
      <mass value="0.1"/>
      <inertia ixx="0.03" ixy="0.0" ixz="0.0" iyy="0.03" iyz="0.0" izz="0.03"/>
    </inertial>
  </link>
  <joint name="joint6" type="continuous">
    <parent link="end"/>
    <child link="manip"/>
    <origin rpy="1.57079632679 0 0" xyz="0 -0.3 0"/>
    <axis xyz="0 0 1"/>
    <limit effort="300" lower="-6.28" upper="6.28" velocity="0.25"/>
  </joint>
</robot>

